Traceback (most recent call last):
  File "/usr3/graduate/shijuan/codes/above/yatsm_v0.6_par/yatsm/mapping/plot_bgw.py", line 289, in <module>
    main()
  File "/projectnb/landsat/users/shijuan/miniconda3/envs/yatsm_v0.6_par/lib/python3.6/site-packages/click/core.py", line 722, in __call__
    return self.main(*args, **kwargs)
  File "/projectnb/landsat/users/shijuan/miniconda3/envs/yatsm_v0.6_par/lib/python3.6/site-packages/click/core.py", line 697, in main
    rv = self.invoke(ctx)
  File "/projectnb/landsat/users/shijuan/miniconda3/envs/yatsm_v0.6_par/lib/python3.6/site-packages/click/core.py", line 895, in invoke
    return ctx.invoke(self.callback, **ctx.params)
  File "/projectnb/landsat/users/shijuan/miniconda3/envs/yatsm_v0.6_par/lib/python3.6/site-packages/click/core.py", line 535, in invoke
    return callback(*args, **kwargs)
  File "/usr3/graduate/shijuan/codes/above/yatsm_v0.6_par/yatsm/mapping/plot_bgw.py", line 287, in main
    map_bgw(npz_file_path, img_file_path, outdir_path)
  File "/usr3/graduate/shijuan/codes/above/yatsm_v0.6_par/yatsm/mapping/plot_bgw.py", line 151, in map_bgw
    data_arr = np.load(npz_file_path)
  File "/projectnb/landsat/users/shijuan/miniconda3/envs/yatsm_v0.6_par/lib/python3.6/site-packages/numpy/lib/npyio.py", line 370, in load
    fid = open(file, "rb")
FileNotFoundError: [Errno 2] No such file or directory: '/projectnb/landsat/projects/ABOVE/CCDC/Bh15v14/Bh15v14.all_breaks.npy.npz'
Finished submitting tile Bh15v14
